Workbook

Sheet Start Here
B1: ZCare Development Checklist
C2: Service: zimasa-zcare-service · Build order M01 → M20, one milestone (domain) at a time · Created 30 September 2026
C3: Open the Dashboard →
B5: How to use this workbook
B6: 1. Find the milestone | C6: Open the Dashboard. The row marked NOW is the only milestone to work on. Every other sheet shows LOCKED until the one before it reaches 100%.
B7: 2. Work the steps in order | C7: On that sheet, go top to bottom: 0 Gate in → 1 Data → 2 Rules → 3 API → 4 Events → 5 Screens → 6 Tests → 7 Docs → 8 Gate out. Server (BE) and screen (FE) rows of the same step may run side by side.
B8: 3. Record progress | C8: Edit only the yellow columns: Status (drop-down), Owner, Date done and Notes / evidence (PR, test name, demo evidence file). Everything else is reference.
B9: 4. N/A counts as done | C9: Use N/A only when a row truly does not apply, and write why in Notes.
B10: 5. Finish a milestone | C10: At 100% the sheet shows Complete, the next sheet unlocks and the Dashboard moves NOW forward. The last Gate out row tags the release.
B11: 6. Close decisions first | C11: The Open Decisions sheet lists conflicts and gaps found in the documents. Each Gate in row names the ones that must be Decided before that milestone starts.
B12: 7. Add a task | C12: Type it in the first empty row below a sheet's list (Task column). Counts and progress include it automatically.
B14: Status values
B15: Not started | C15: Work has not begun.
B16: In progress | C16: Someone is working on it now.
B17: Blocked | C17: Cannot continue; say what blocks it in Notes (often an Open Decision).
B18: Done | C18: Finished and verified; evidence in Notes.
B19: N/A | C19: Does not apply; reason in Notes.
B21: Steps inside every milestone
B22: 0 Gate in | C22: Previous milestone signed off; specs re-read; blocking decisions closed.
B23: 1 Data | C23: JPA entities for the domain's own tables, repositories, specifications, database-error mapping.
B24: 2 Rules | C24: Services: lifecycles, invariants and guardrails. All business logic lives here.
B25: 3 API | C25: Controllers and DTOs for the endpoints in 04B, inside the standard envelope.
B26: 4 Events | C26: Domain events written to the outbox; adapters behind ports.
B27: 5 Screens | C27: Web-app screens (separate React project) for the same milestone.
B28: 6 Tests | C28: Unit, integration (PostgreSQL as zc_app), security, consent and domain-specific tests.
B29: 7 Docs | C29: OpenAPI/AsyncAPI, knowledge base, CHANGELOG, demo evidence.
B30: 8 Gate out | C30: Done-when demonstrated, reviews signed, release tagged.
B32: Team codes
B33: Codes | C33: BE server · FE web app · DB database · QA testing · PO product owner / delivery lead · CLIN clinician (Aga Khan) · PRIV Privacy / DPO · SEC security · OPS operations
B35: Example of a filled-in row
B36: # · Step · Task | C36: Status · Owner · Date done · Notes / evidence
B37: M07-10 · 2 Rules | C37: ConsentGateService (one for everything) → Done · dev-a · 2026-11-18 · MR !42; ConsentGateServiceTest and ConsentGateIT green
B39: Source key (Ref column)
B40: RM | C40: ZCare Migration & Development Roadmap v0.3 (docs/ZCare_Migration & Development_Roadmap_Executive_v0.3.docx.pdf)
B41: PRD, ADD | C41: docs/supporting docs/04-zcare_care_disease_management_PRD.md and 04-ADD-001 addendum
B42: 04A – 04F | C42: Domain model, API & events, UX & screens (S-xx, W-x, journeys), data model, AI governance, implementation guide (docs/supporting docs)
B43: AGENTS, GUIDE, DM | C43: AGENTS.md / AGENT_GUARDRAILS.md, Engineering Documentation Generation Guide, DOMAIN_MODEL.md
B44: UAT | C44: UAT-01..28 scripts (trial repo zimasa-zcare/docs/uat/uat-scripts.md)
B45: ADR-000n, mig-NN | C45: Service docs/adr and src/main/resources/db/changelog/migrations/20260929_NN_*.xml
B46: STD, LAY | C46: Versioning & Coding Standards v1.0.0 and Project Layout & Arrangement Rules v1.0 (docs/*.pdf)
...

Sheet Dashboard
A1: ZCare Development Dashboard
A2: One milestone at a time, top to bottom. "Can start" turns Yes only when the milestone above is 100% complete; NOW marks the one to work on. Click a name to open its sheet.
A3: Now: | C3: =IFERROR(INDEX($C$6:$C$25,MATCH("NOW",$L$6:$L$25,0)),"All milestones complete") -> Database Setup | G3: Overall: | I3: =IF(SUM(F6:F25)=0,0,SUM(G6:G25)/SUM(F6:F25)) -> 0.014440433 | K3: Open decisions: | N3: =COUNTIF('Open Decisions'!$F$5:$F$200,"Open") -> 30
A5: Order | B5: ID | C5: Milestone | D5: Sprints | E5: Depends on | F5: Tasks | G5: Done | H5: Blocked | I5: Progress | J5: State | K5: Can start? | L5: Now | M5: Open decisions | N5: Release | O5: Done when
A6: 1 | B6: M01 | C6: Database Setup | D6: S1–S2 | E6: — | F6: ='M01 Database'!$D$6 -> 15 | G6: ='M01 Database'!$F$6 -> 8 | H6: ='M01 Database'!$H$6 -> 0 | I6: ='M01 Database'!$B$6 -> 0.53333333 | J6: ='M01 Database'!$J$6 -> In progress | K6: Yes | L6: =IF(AND(K6="Yes",I6<1),"NOW","") -> NOW | M6: =COUNTIFS('Open Decisions'!$D$5:$D$200,"*"&B6&"*",'Open Decisions'!$F$5:$F$200,"Open") -> 1 | N6: v0.1.0 | O6: The database matches the agreed design exactly, and one client cannot see another's data.
A7: 2 | B7: M02 | C7: Platform Foundations | D7: S3–S5 | E7: M01 | F7: ='M02 Platform'!$D$6 -> 33 | G7: ='M02 Platform'!$F$6 -> 0 | H7: ='M02 Platform'!$H$6 -> 0 | I7: ='M02 Platform'!$B$6 -> 0 | J7: ='M02 Platform'!$J$6 -> Not started | K7: =IF(I6=1,"Yes","No") -> No | L7: =IF(AND(K7="Yes",I7<1),"NOW","") | M7: =COUNTIFS('Open Decisions'!$D$5:$D$200,"*"&B7&"*",'Open Decisions'!$F$5:$F$200,"Open") -> 12 | N7: v0.2.0 | O7: A user signs in and sees only what their role allows.
A8: 3 | B8: M03 | C8: Tenant & Access | D8: S6–S7 | E8: M02 | F8: ='M03 Access'!$D$6 -> 32 | G8: ='M03 Access'!$F$6 -> 0 | H8: ='M03 Access'!$H$6 -> 0 | I8: ='M03 Access'!$B$6 -> 0 | J8: ='M03 Access'!$J$6 -> Not started | K8: =IF(I7=1,"Yes","No") -> No | L8: =IF(AND(K8="Yes",I8<1),"NOW","") | M8: =COUNTIFS('Open Decisions'!$D$5:$D$200,"*"&B8&"*",'Open Decisions'!$F$5:$F$200,"Open") -> 4 | N8: v0.3.0 | O8: A newly created user signs in with the correct access, and no password or secret is stored in the database or shown on screen.
A9: 4 | B9: M04 | C9: Programme Management | D9: S8–S10 | E9: M03 | F9: ='M04 Programme'!$D$6 -> 30 | G9: ='M04 Programme'!$F$6 -> 0 | H9: ='M04 Programme'!$H$6 -> 0 | I9: ='M04 Programme'!$B$6 -> 0 | J9: ='M04 Programme'!$J$6 -> Not started | K9: =IF(I8=1,"Yes","No") -> No | L9: =IF(AND(K9="Yes",I9<1),"NOW","") | M9: =COUNTIFS('Open Decisions'!$D$5:$D$200,"*"&B9&"*",'Open Decisions'!$F$5:$F$200,"Open") -> 2 | N9: v0.4.0 | O9: A programme cannot go live without clinician approval, and a published version cannot be edited.
A10: 5 | B10: M05 | C10: External References | D10: S11 | E10: M04 | F10: ='M05 Reference'!$D$6 -> 26 | G10: ='M05 Reference'!$F$6 -> 0 | H10: ='M05 Reference'!$H$6 -> 0 | I10: ='M05 Reference'!$B$6 -> 0 | J10: ='M05 Reference'!$J$6 -> Not started | K10: =IF(I9=1,"Yes","No") -> No | L10: =IF(AND(K10="Yes",I10<1),"NOW","") | M10: =COUNTIFS('Open Decisions'!$D$5:$D$200,"*"&B10&"*",'Open Decisions'!$F$5:$F$200,"Open") -> 2 | N10: v0.5.0 | O10: Every copied detail shows its source and date, and if ZPS is down users see a clear message, never a silent gap.
A11: 6 | B11: M06 | C11: Population & Cohort | D11: S12–S13 | E11: M05 | F11: ='M06 Cohort'!$D$6 -> 27 | G11: ='M06 Cohort'!$F$6 -> 0 | H11: ='M06 Cohort'!$H$6 -> 0 | I11: ='M06 Cohort'!$B$6 -> 0 | J11: ='M06 Cohort'!$J$6 -> Not started | K11: =IF(I10=1,"Yes","No") -> No | L11: =IF(AND(K11="Yes",I11<1),"NOW","") | M11: =COUNTIFS('Open Decisions'!$D$5:$D$200,"*"&B11&"*",'Open Decisions'!$F$5:$F$200,"Open") -> 1 | N11: v0.6.0 | O11: A member sent by the payer appears as ready to invite, and a message without a valid signature is rejected, logged and changes nothing.
A12: 7 | B12: M07 | C12: Enrolment, Consent & Preferences | D12: S14–S16 | E12: M06 | F12: ='M07 Enrolment'!$D$6 -> 38 | G12: ='M07 Enrolment'!$F$6 -> 0 | H12: ='M07 Enrolment'!$H$6 -> 0 | I12: ='M07 Enrolment'!$B$6 -> 0 | J12: ='M07 Enrolment'!$J$6 -> Not started | K12: =IF(I11=1,"Yes","No") -> No | L12: =IF(AND(K12="Yes",I12<1),"NOW","") | M12: =COUNTIFS('Open Decisions'!$D$5:$D$200,"*"&B12&"*",'Open Decisions'!$F$5:$F$200,"Open") -> 3 | N12: v0.7.0 | O12: No one can be activated without valid consent, and withdrawn consent blocks every action and cancels follow-on work.
A13: 8 | B13: M08 | C13: Assessment & Risk | D13: S17–S18 | E13: M07 | F13: ='M08 Assessment'!$D$6 -> 29 | G13: ='M08 Assessment'!$F$6 -> 0 | H13: ='M08 Assessment'!$H$6 -> 0 | I13: ='M08 Assessment'!$B$6 -> 0 | J13: ='M08 Assessment'!$J$6 -> Not started | K13: =IF(I12=1,"Yes","No") -> No | L13: =IF(AND(K13="Yes",I13<1),"NOW","") | M13: =COUNTIFS('Open Decisions'!$D$5:$D$200,"*"&B13&"*",'Open Decisions'!$F$5:$F$200,"Open") -> 2 | N13: v0.8.0 | O13: The same answers always give the same score, and every override has a reason.
A14: 9 | B14: M09 | C14: Care Planning | D14: S19–S21 | E14: M08 | F14: ='M09 Care Plan'!$D$6 -> 32 | G14: ='M09 Care Plan'!$F$6 -> 0 | H14: ='M09 Care Plan'!$H$6 -> 0 | I14: ='M09 Care Plan'!$B$6 -> 0 | J14: ='M09 Care Plan'!$J$6 -> Not started | K14: =IF(I13=1,"Yes","No") -> No | L14: =IF(AND(K14="Yes",I14<1),"NOW","") | M14: =COUNTIFS('Open Decisions'!$D$5:$D$200,"*"&B14&"*",'Open Decisions'!$F$5:$F$200,"Open") -> 3 | N14: v0.9.0 | O14: Only a clinician activates a plan, authors cannot approve their own plans, and each member has one active plan.
A15: 10 | B15: M10 | C15: Care Work | D15: S22–S23 | E15: M09 | F15: ='M10 Care Work'!$D$6 -> 32 | G15: ='M10 Care Work'!$F$6 -> 0 | H15: ='M10 Care Work'!$H$6 -> 0 | I15: ='M10 Care Work'!$B$6 -> 0 | J15: ='M10 Care Work'!$J$6 -> Not started | K15: =IF(I14=1,"Yes","No") -> No | L15: =IF(AND(K15="Yes",I15<1),"NOW","") | M15: =COUNTIFS('Open Decisions'!$D$5:$D$200,"*"&B15&"*",'Open Decisions'!$F$5:$F$200,"Open") -> 2 | N15: v0.10.0 | O15: Each care manager has a prioritised queue that loads in under half a second at pilot scale, and overdue work is flagged.
A16: 11 | B16: M11 | C16: Referrals & Provider Participation | D16: S24–S25 | E16: M10 | F16: ='M11 Referral'!$D$6 -> 30 | G16: ='M11 Referral'!$F$6 -> 0 | H16: ='M11 Referral'!$H$6 -> 0 | I16: ='M11 Referral'!$B$6 -> 0 | J16: ='M11 Referral'!$J$6 -> Not started | K16: =IF(I15=1,"Yes","No") -> No | L16: =IF(AND(K16="Yes",I16<1),"NOW","") | M16: =COUNTIFS('Open Decisions'!$D$5:$D$200,"*"&B16&"*",'Open Decisions'!$F$5:$F$200,"Open") -> 1 | N16: v0.11.0 | O16: A referral closes only on provider or clinician confirmation; a member's own report never closes it.
A17: 12 | B17: M12 | C17: Medication Coordination | D17: S26 | E17: M11 | F17: ='M12 Medication'!$D$6 -> 26 | G17: ='M12 Medication'!$F$6 -> 0 | H17: ='M12 Medication'!$H$6 -> 0 | I17: ='M12 Medication'!$B$6 -> 0 | J17: ='M12 Medication'!$J$6 -> Not started | K17: =IF(I16=1,"Yes","No") -> No | L17: =IF(AND(K17="Yes",I17<1),"NOW","") | M17: =COUNTIFS('Open Decisions'!$D$5:$D$200,"*"&B17&"*",'Open Decisions'!$F$5:$F$200,"Open") -> 0 | N17: v0.12.0 | O17: A refill is "confirmed" only by a pharmacy or provider, and the database enforces it.
A18: 13 | B18: M13 | C18: Observation & Monitoring | D18: S27–S28 | E18: M12 | F18: ='M13 Observation'!$D$6 -> 29 | G18: ='M13 Observation'!$F$6 -> 0 | H18: ='M13 Observation'!$H$6 -> 0 | I18: ='M13 Observation'!$B$6 -> 0 | J18: ='M13 Observation'!$J$6 -> Not started | K18: =IF(I17=1,"Yes","No") -> No | L18: =IF(AND(K18="Yes",I18<1),"NOW","") | M18: =COUNTIFS('Open Decisions'!$D$5:$D$200,"*"&B18&"*",'Open Decisions'!$F$5:$F$200,"Open") -> 4 | N18: v0.13.0 | O18: A reading over the limit always creates a clinician review.
A19: 14 | B19: M14 | C19: Care Gaps | D19: S29–S30 | E19: M13 | F19: ='M14 Care Gaps'!$D$6 -> 27 | G19: ='M14 Care Gaps'!$F$6 -> 0 | H19: ='M14 Care Gaps'!$H$6 -> 0 | I19: ='M14 Care Gaps'!$B$6 -> 0 | J19: ='M14 Care Gaps'!$J$6 -> Not started | K19: =IF(I18=1,"Yes","No") -> No | L19: =IF(AND(K19="Yes",I19<1),"NOW","") | M19: =COUNTIFS('Open Decisions'!$D$5:$D$200,"*"&B19&"*",'Open Decisions'!$F$5:$F$200,"Open") -> 1 | N19: v0.14.0 | O19: Each gap shows why it was raised, and running the check twice never creates duplicates.
A20: 15 | B20: M15 | C20: Engagement & Outreach | D20: S31–S34 | E20: M14 | F20: ='M15 Engagement'!$D$6 -> 34 | G20: ='M15 Engagement'!$F$6 -> 0 | H20: ='M15 Engagement'!$H$6 -> 0 | I20: ='M15 Engagement'!$B$6 -> 0 | J20: ='M15 Engagement'!$J$6 -> Not started | K20: =IF(I19=1,"Yes","No") -> No | L20: =IF(AND(K20="Yes",I20<1),"NOW","") | M20: =COUNTIFS('Open Decisions'!$D$5:$D$200,"*"&B20&"*",'Open Decisions'!$F$5:$F$200,"Open") -> 3 | N20: v0.15.0 | O20: "STOP" halts all contact straight away, and a consent withdrawal always wins over a message about to be sent.
A21: 16 | B21: M16 | C21: Outcomes & Proof | D21: S35–S36 | E21: M15 | F21: ='M16 Outcomes'!$D$6 -> 26 | G21: ='M16 Outcomes'!$F$6 -> 0 | H21: ='M16 Outcomes'!$H$6 -> 0 | I21: ='M16 Outcomes'!$B$6 -> 0 | J21: ='M16 Outcomes'!$J$6 -> Not started | K21: =IF(I20=1,"Yes","No") -> No | L21: =IF(AND(K21="Yes",I21<1),"NOW","") | M21: =COUNTIFS('Open Decisions'!$D$5:$D$200,"*"&B21&"*",'Open Decisions'!$F$5:$F$200,"Open") -> 0 | N21: v0.16.0 | O21: Employers never see individuals, and groups under 10 are withheld, never estimated.
A22: 17 | B22: M17 | C22: Audit & Security | D22: S37–S38 | E22: M16 | F22: ='M17 Audit'!$D$6 -> 25 | G22: ='M17 Audit'!$F$6 -> 0 | H22: ='M17 Audit'!$H$6 -> 0 | I22: ='M17 Audit'!$B$6 -> 0 | J22: ='M17 Audit'!$J$6 -> Not started | K22: =IF(I21=1,"Yes","No") -> No | L22: =IF(AND(K22="Yes",I22<1),"NOW","") | M22: =COUNTIFS('Open Decisions'!$D$5:$D$200,"*"&B22&"*",'Open Decisions'!$F$5:$F$200,"Open") -> 1 | N22: v0.17.0 | O22: History cannot be edited or deleted, and no serious security issue is open.
A23: 18 | B23: M18 | C23: Integration Persistence | D23: S39–S41 | E23: M17 | F23: ='M18 Integration'!$D$6 -> 27 | G23: ='M18 Integration'!$F$6 -> 0 | H23: ='M18 Integration'!$H$6 -> 0 | I23: ='M18 Integration'!$B$6 -> 0 | J23: ='M18 Integration'!$J$6 -> Not started | K23: =IF(I22=1,"Yes","No") -> No | L23: =IF(AND(K23="Yes",I23<1),"NOW","") | M23: =COUNTIFS('Open Decisions'!$D$5:$D$200,"*"&B23&"*",'Open Decisions'!$F$5:$F$200,"Open") -> 3 | N23: v0.18.0 | O23: No failure is silent: every failed delivery appears as a task for an administrator.
A24: 19 | B24: M19 | C24: AI (switched off) | D24: S42 | E24: M18 | F24: ='M19 AI'!$D$6 -> 21 | G24: ='M19 AI'!$F$6 -> 0 | H24: ='M19 AI'!$H$6 -> 0 | I24: ='M19 AI'!$B$6 -> 0 | J24: ='M19 AI'!$J$6 -> Not started | K24: =IF(I23=1,"Yes","No") -> No | L24: =IF(AND(K24="Yes",I24<1),"NOW","") | M24: =COUNTIFS('Open Decisions'!$D$5:$D$200,"*"&B24&"*",'Open Decisions'!$F$5:$F$200,"Open") -> 0 | N24: v0.19.0 | O24: Everything works with AI switched off, and checks prove no AI is called anywhere.
A25: 20 | B25: M20 | C25: Testing & Acceptance | D25: S43–S48 | E25: M19 | F25: ='M20 Acceptance'!$D$6 -> 15 | G25: ='M20 Acceptance'!$F$6 -> 0 | H25: ='M20 Acceptance'!$H$6 -> 0 | I25: ='M20 Acceptance'!$B$6 -> 0 | J25: ='M20 Acceptance'!$J$6 -> Not started | K25: =IF(I24=1,"Yes","No") -> No | L25: =IF(AND(K25="Yes",I25<1),"NOW","") | M25: =COUNTIFS('Open Decisions'!$D$5:$D$200,"*"&B25&"*",'Open Decisions'!$F$5:$F$200,"Open") -> 3 | N25: v1.0.0 | O25: All tests pass, users sign off, no serious defects remain, and the go/no-go decision is recorded.
C26: Total | F26: =SUM(F6:F25) -> 554 | G26: =SUM(G6:G25) -> 8 | H26: =SUM(H6:H25) -> 0 | I26: =I3 -> 0.014440433

Sheet M01 Database
A1: M01 · Database Setup | J1: ← Dashboard
A2: Goal | B2: Create the new database from the agreed design, with tenant separation built in from day one.
A3: Owns | B3: All 60 zc_* tables, shared functions, roles zc_app and zc_housekeeping, RLS (20 Liquibase files, 20260929_01–20)
A4: Plan | B4: Depends on — · Sprints S1–S2 · Screens FE-M1 web-app project · Release v0.1.0
A5: Done when | B5: The database matches the agreed design exactly, and one client cannot see another's data.
A6: Progress | B6: =IF(D6=0,0,F6/D6) -> 0.53333333 | C6: Tasks | D6: =COUNTA(C9:C400) -> 15 | E6: Done or N/A | F6: =COUNTIF(G9:G400,"Done")+COUNTIF(G9:G400,"N/A") -> 8 | G6: Blocked | H6: =COUNTIF(G9:G400,"Blocked") -> 0 | I6: State | J6: =IF(B6=1,"Complete",IF(H6>0,"Blocked",IF(F6+COUNTIF(G9:G400,"In progress")=0,"Not started","In progress"))) -> In progress
A7: READY: first milestone, no prerequisite. Work the steps in order, 0 Gate in to 8 Gate out.
A8: # | B8: Step | C8: Task | D8: Detail / done when | E8: Team | F8: Ref | G8: Status | H8: Owner | I8: Date done | J8: Notes / evidence
A9: M01-01 | B9: 0 Gate in | C9: Agree db.sql V001–V005 as the baseline | D9: Baseline recorded, with the trial's real V003 replacing the design V003. | E9: DB, PO | F9: ADR-0004 | G9: Done | J9: ADR-0004 accepted 29 Sep 2026
A10: M01-02 | B10: 0 Gate in | C10: Settle design differences with today's system | D10: Confirm reply-message categories, WhatsApp settings and other R2 items; record each outcome. | E10: DB, PO | F10: RM R2; ADR-0004 | G10: Not started
A11: M01-03 | B11: 1 Data | C11: Changelog with one file per concern | D11: 20 XML changesets carrying PostgreSQL SQL; master holds includes only; HALT preconditions and rollbacks everywhere. | E11: DB | F11: ADR-0003; LAY DB-02..10 | G11: Done | J11: ChangelogConventionsTest 7/7 green (30 Sep)
A12: M01-04 | B12: 1 Data | C12: Shared functions and triggers | D12: zc_current_tenant, zc_touch_row, zc_forbid_change, zc_forbid_pinned_change, zc_forbid_published_version_change. | E12: DB | F12: mig-01 | G12: Done | J12: mig-01
A13: M01-05 | B13: 1 Data | C13: Application and housekeeping roles | D13: zc_app owns nothing, cannot DELETE/TRUNCATE or bypass RLS; zc_housekeeping NOLOGIN. | E13: DB | F13: mig-02; 04D §12.4 | G13: Done | J13: ApplicationRolePostureIT 6/6 green
A14: M01-06 | B14: 1 Data | C14: Row-level security on tenant tables | D14: Forced RLS policy on 56 tenant tables; exempt: zc_tenant, zc_tenant_whatsapp, zc_user, zc_security_event. | E14: DB | F14: docs/database/README.md; mig-20 | G14: Done | J14: TenantIsolationIT 7/7 green
A15: M01-07 | B15: 1 Data | C15: Append-only tables | D15: 9 tables protected by trigger and privilege (config history, responses, risk, plan review, assignment history, provider action, report snapshot, audit, security event). | E15: DB | F15: 04D §11 | G15: Done | J15: ApplicationRolePostureIT
A16: M01-08 | B16: 1 Data | C16: Seed data: sample programmes and test people | D16: Liquibase context "seed"/"test-data": diabetes and workplace-wellness programmes, synthetic members marked [SYNTHETIC]; never loaded for a real tenant. | E16: DB, CLIN | F16: RM BE-M1; 04F §19; LAY DB-16 | G16: Not started
A17: M01-09 | B17: 5 Screens | C17: FE-M1: web-app project | D17: Separate React 18 + TypeScript + Vite + MUI + Tailwind project with Zimasa tokens; builds automatically; Keycloak client registered. | E17: FE | F17: RM FE-M1 | G17: Not started | J17: Outside this repository; status unknown
A18: M01-10 | B18: 6 Tests | C18: Rebuild from scratch equals the agreed design | D18: Changelog and agreed-design SQL produce identical catalogues; re-running changes nothing. | E18: DB | F18: RM BE-M1 | G18: Done | J18: AgreedDesignParityIT 1/1, ChangelogMigrationIT 3/3
A19: M01-11 | B19: 6 Tests | C19: 04D behavioural invariant suite | D19: Promote the 04D §25.1 assertions still missing: T1–T12, T14, P1–P4 (incl. P4 vocabulary sweep), G1–G5. | E19: DB, QA | F19: 04D §25.1; 04F §18 | G19: Not started
A20: M01-12 | B20: 7 Docs | C20: Database docs | D20: docs/database/README.md, migration-plan.md, guides/local-setup.md, compose file and setup scripts. | E20: DB | F20: LAY DOC | G20: Done | J20: Present in repo
A21: M01-13 | B21: 7 Docs | C21: Put the service under git with CI | D21: Create the repository, protect main, name the canonical remote; CI runs ./mvnw verify on every commit. | E21: BE, OPS | F21: STD BRN-01, BRN-08; 04F §18; OD-06 | G21: Not started | J21: Directory is not a git repository yet
A22: M01-14 | B22: 8 Gate out | C22: Done-when demonstrated | D22: The database matches the agreed design exactly, and one client cannot see another's data. | E22: PO | F22: RM §3 | G22: Not started
A23: M01-15 | B23: 8 Gate out | C23: Release v0.1.0 tagged | D23: Annotated tag from a green pipeline; CHANGELOG created with the first section. | E23: BE | F23: STD REL-01, REL-03 | G23: Not started

Sheet M02 Platform
A1: M02 · Platform Foundations | J1: ← Dashboard
A2: Goal | B2: Shared plumbing every feature relies on: sign-in, permissions, one response format, errors, idempotency, audit and outbox writers.
A3: Owns | B3: Packages config, security, tenant, common (no tables of their own)
A4: Plan | B4: Depends on M01 · Sprints S3–S5 · Screens FE-M2 sign-in, role menus, shared components · Release v0.2.0
A5: Done when | B5: A user signs in and sees only what their role allows.
A6: Progress | B6: =IF(D6=0,0,F6/D6) -> 0 | C6: Tasks | D6: =COUNTA(C9:C400) -> 33 | E6: Done or N/A | F6: =COUNTIF(G9:G400,"Done")+COUNTIF(G9:G400,"N/A") -> 0 | G6: Blocked | H6: =COUNTIF(G9:G400,"Blocked") -> 0 | I6: State | J6: =IF(B6=1,"Complete",IF(H6>0,"Blocked",IF(F6+COUNTIF(G9:G400,"In progress")=0,"Not started","In progress"))) -> Not started
A7: =IF('M01 Database'!$B$6=1,"READY: M01 is complete. Work the steps in order, 0 Gate in to 8 Gate out.","LOCKED: finish M01 Database first. Do not start work on this sheet.") -> LOCKED: finish M01 Database first. Do not start work on this sheet.
A8: # | B8: Step | C8: Task | D8: Detail / done when | E8: Team | F8: Ref | G8: Status | H8: Owner | I8: Date done | J8: Notes / evidence
A9: M02-01 | B9: 0 Gate in | C9: Confirm M01 is signed off | D9: Dashboard shows M01 at 100%. | E9: PO | F9: RM §2.2 | G9: Not started
A10: M02-02 | B10: 0 Gate in | C10: Close the open decisions needed here | D10: OD-01 to OD-08, OD-10, OD-11, OD-18 and OD-28 marked Decided, each with an ADR (start with ADR-0005 response style). | E10: PO, BE | F10: OD sheet | G10: Not started
A11: M02-03 | B11: 1 Data | C11: Add dependencies with their first use | D11: Starters web, validation, data-jpa, security, oauth2-resource-server, actuator; MapStruct, springdoc; runtime postgresql and liquibase. Versions from the Boot BOM only. | E11: BE | F11: LAY BLD-03, BLD-07; STD DEP-01 | G11: Not started
A12: M02-04 | B12: 1 Data | C12: Application class and configuration | D12: ZimasaZcareApplication; application.yml (production-safe), -local, -test; every value from ${VAR}; .env.example complete. | E12: BE | F12: LAY CFG-01..06; STD RUN-03 | G12: Not started
A13: M02-05 | B13: 1 Data | C13: Datasource and JPA settings | D13: Connect as zc_app; migrations run by the owner account; ddl-auto=validate; open-in-view=false. | E13: BE | F13: 04D §12.4; STD SCH-07, JPA-04 | G13: Not started
A14: M02-06 | B14: 1 Data | C14: Tenant context per transaction | D14: Tenant from the token; set_config('zcare.tenant_id', id, true) at transaction start; cleared in finally; copied to async threads. | E14: BE | F14: tenant/package-info; 04F §9; STD RES-10 | G14: Not started
A15: M02-07 | B15: 2 Rules | C15: Audit writer | D15: Every material write adds a zc_domain_audit row; its operation equals the envelope auditTrail.operation. | E15: BE | F15: 04A INV-7; 04B §5; OD-08 | G15: Not started
A16: M02-08 | B16: 2 Rules | C16: Security-event writer | D16: Denials, tenant violations and invalid webhook signatures written to zc_security_event. | E16: BE | F16: 04D §11 | G16: Not started
A17: M02-09 | B17: 2 Rules | C17: Idempotency middleware | D17: Idempotency-Key on every mutation; (key, user, route) kept at least 24 h; replay returns the same envelope; different body gives IDEMPOTENCY_KEY_CONFLICT. | E17: BE | F17: 04B §7; 04D §18 | G17: Not started
A18: M02-10 | B18: 2 Rules | C18: Transactional outbox writer | D18: Domain events written in the same transaction as the aggregate; one aggregate per transaction. | E18: BE | F18: 04A §15; 04D §17 | G18: Not started
A19: M02-11 | B19: 2 Rules | C19: Consent-gate extension point | D19: One ConsentGate interface called at command, dispatch and query; implementation lands in M07. | E19: BE | F19: 04D §9.4; RM BE-M7 | G19: Not started
A20: M02-12 | B20: 3 API | C20: Response envelope | D20: ENG-STD-SB-001 8 fields; data never a bare array; 1-based PagedResponse; nextActions allow-list. | E20: BE | F20: 04B §5, §8; OD-01 | G20: Not started
... A41: M02-33 | B41: 8 Gate out | C41: Release v0.2.0 tagged | D41: Annotated tag from a green pipeline; Dashboard shows 100%. | E41: BE | F41: STD REL-01, REL-04 | G41: Not started

Sheet M03 Access
A1: M03 · Tenant & Access | J1: ← Dashboard
A2: Goal | B2: Administrators manage client organisations, staff accounts, roles, settings and each client's WhatsApp number.
A3: Owns | B3: domains.access: zc_tenant, zc_organisation, zc_role_assignment, zc_break_glass_grant, zc_config_history, zc_user, zc_tenant_whatsapp (mig-03)
A4: Plan | B4: Depends on M02 · Sprints S6–S7 · Screens S-18 · Release v0.3.0
A5: Done when | B5: A newly created user signs in with the correct access, and no password or secret is stored in the database or shown on screen.
A6: Progress | B6: =IF(D6=0,0,F6/D6) -> 0 | C6: Tasks | D6: =COUNTA(C9:C400) -> 32 | E6: Done or N/A | F6: =COUNTIF(G9:G400,"Done")+COUNTIF(G9:G400,"N/A") -> 0 | G6: Blocked | H6: =COUNTIF(G9:G400,"Blocked") -> 0 | I6: State | J6: =IF(B6=1,"Complete",IF(H6>0,"Blocked",IF(F6+COUNTIF(G9:G400,"In progress")=0,"Not started","In progress"))) -> Not started
A7: =IF('M02 Platform'!$B$6=1,"READY: M02 is complete. Work the steps in order, 0 Gate in to 8 Gate out.","LOCKED: finish M02 Platform first. Do not start work on this sheet.") -> LOCKED: finish M02 Platform first. Do not start work on this sheet.
A8: # | B8: Step | C8: Task | D8: Detail / done when | E8: Team | F8: Ref | G8: Status | H8: Owner | I8: Date done | J8: Notes / evidence
A9: M03-01 | B9: 0 Gate in | C9: Confirm M02 is signed off | D9: Dashboard shows M02 at 100% and its Gate out rows are Done. Do not start this sheet before that. | E9: PO | F9: RM §2.2 | G9: Not started
A10: M03-02 | B10: 0 Gate in | C10: Re-read this domain's specs | D10: PRD §6.9, §8.15, §9.2; 04A §17–18; 04B §2; 04C S-18, §9, §12; ADD A9; mig-03. | E10: BE, FE | F10: AGENTS "Source precedence" | G10: Not started
A11: M03-03 | B11: 0 Gate in | C11: Close the open decisions needed here | D11: Open Decisions sheet: OD-12, OD-13, OD-14, OD-16 marked Decided, with the ADR or doc that records each. | E11: PO, BE | F11: OD sheet | G11: Not started
A12: M03-04 | B12: 1 Data | C12: Map owned tables to JPA entities | D12: zc_tenant, zc_organisation, zc_role_assignment, zc_break_glass_grant, zc_config_history, zc_user, zc_tenant_whatsapp. Identity ids never supplied; @Version on row_version; tenant_id and created_* not updatable; entities stay inside the service layer. | E12: BE | F12: mig-03; 04D §11; ADR-0002 | G12: Not started
A13: M03-05 | B13: 1 Data | C13: Map append-only tables as insert-only | D13: zc_config_history: INSERT and SELECT only; a change is a new row (trigger and privilege already enforce it). | E13: BE | F13: 04D §11; mig-20 | G13: Not started
A14: M03-06 | B14: 1 Data | C14: Repositories and Specifications | D14: Spring Data repositories and <X>Specifications for search; every query runs inside the tenant context (RLS); lists are paged thin projections. | E14: BE | F14: 04F §8; STD JPA-11 | G14: Not started
A15: M03-07 | B15: 1 Data | C15: Translate constraint violations to exception codes | D15: uq_zc_role_assignment_no_overlap → overlapping grant (WARNING); append-only config history → ZCARE_CONFIG_HISTORY_IMMUTABLE. | E15: BE | F15: 04D §9.3; 04B §6 | G15: Not started
A16: M03-08 | B16: 2 Rules | C16: Migration: remove secrets from the database | D16: New changeset: zc_user without password_hash; zc_tenant_whatsapp stores a secret reference, not the access token. Update the agreed-design fixture. | E16: DB | F16: RM §1.1; ADR-0004; OD-12, OD-13 | G16: Not started
A17: M03-09 | B17: 2 Rules | C17: Staff accounts in Keycloak | D17: Create users through the Keycloak Admin API; keep only a local copy of role and organisation; provider users carry the org claim. | E17: BE | F17: RM BE-M3; ADD A9 | G17: Not started
A18: M03-10 | B18: 2 Rules | C18: Organisations | D18: Create, suspend, inactivate; code unique per tenant. | E18: BE | F18: ZCR-ADM-001; mig-03 | G18: Not started
A19: M03-11 | B19: 2 Rules | C19: Role grants | D19: Time-bound grants; no overlapping grant; revocation needs who, when and reason. | E19: BE | F19: mig-03 ck_…_revocation | G19: Not started
A20: M03-12 | B20: 2 Rules | C20: Break-glass access | D20: Reason and typed confirmation required; expires by itself; every use written as break_glass_use. | E20: BE, SEC | F20: PRD §9.2; 04C §8, §12 | G20: Not started
... A40: M03-32 | B40: 8 Gate out | C40: Release v0.3.0 tagged | D40: Annotated tag v0.3.0 from a green pipeline; CHANGELOG section dated; next SNAPSHOT set. Dashboard now shows 100%. | E40: BE | F40: STD REL-01, REL-04, REL-07 | G40: Not started

Sheet M04 Programme
A1: M04 · Programme Management | J1: ← Dashboard
A2: Goal | B2: Programme teams design care programmes, and a clinician approves them before use.
A3: Owns | B3: domains.programme: zc_programme, zc_programme_version, zc_assessment_template(_version), zc_gap_rule, zc_task_template, zc_referral_type, zc_observation_type, zc_goal_type, zc_outcome_definition (mig-05)
A4: Plan | B4: Depends on M03 · Sprints S8–S10 · Screens S-07 · Release v0.4.0
A5: Done when | B5: A programme cannot go live without clinician approval, and a published version cannot be edited.
A6: Progress | B6: =IF(D6=0,0,F6/D6) -> 0 | C6: Tasks | D6: =COUNTA(C9:C400) -> 30 | E6: Done or N/A | F6: =COUNTIF(G9:G400,"Done")+COUNTIF(G9:G400,"N/A") -> 0 | G6: Blocked | H6: =COUNTIF(G9:G400,"Blocked") -> 0 | I6: State | J6: =IF(B6=1,"Complete",IF(H6>0,"Blocked",IF(F6+COUNTIF(G9:G400,"In progress")=0,"Not started","In progress"))) -> Not started
A7: =IF('M03 Access'!$B$6=1,"READY: M03 is complete. Work the steps in order, 0 Gate in to 8 Gate out.","LOCKED: finish M03 Access first. Do not start work on this sheet.") -> LOCKED: finish M03 Access first. Do not start work on this sheet.
A8: # | B8: Step | C8: Task | D8: Detail / done when | E8: Team | F8: Ref | G8: Status | H8: Owner | I8: Date done | J8: Notes / evidence
A9: M04-01 | B9: 0 Gate in | C9: Confirm M03 is signed off | D9: Dashboard shows M03 at 100% and its Gate out rows are Done. Do not start this sheet before that. | E9: PO | F9: RM §2.2 | G9: Not started
A10: M04-02 | B10: 0 Gate in | C10: Re-read this domain's specs | D10: PRD §8.2, §9.10; 04A §7.1; 04B §10 (publish); 04C S-07; 04D §2.3, §20; ADD Part E; mig-05. | E10: BE, FE | F10: AGENTS "Source precedence" | G10: Not started
A11: M04-03 | B11: 0 Gate in | C11: Close the open decisions needed here | D11: Open Decisions sheet: OD-15, OD-16, OD-17 marked Decided, with the ADR or doc that records each. | E11: PO, BE | F11: OD sheet | G11: Not started
A12: M04-04 | B12: 1 Data | C12: Map owned tables to JPA entities | D12: zc_programme, zc_programme_version, zc_assessment_template(_version), zc_gap_rule, zc_task_template, zc_referral_type, zc_observation_type, zc_goal_type, zc_outcome_definition. Identity ids never supplied; @Version on row_version; tenant_id and created_* not updatable; entities stay inside the service layer. | E12: BE | F12: mig-05; 04D §11; ADR-0002 | G12: Not started
A13: M04-05 | B13: 1 Data | C13: Repositories and Specifications | D13: Spring Data repositories and <X>Specifications for search; every query runs inside the tenant context (RLS); lists are paged thin projections. | E13: BE | F13: 04F §8; STD JPA-11 | G13: Not started
A14: M04-06 | B14: 1 Data | C14: Translate constraint violations to exception codes | D14: trg_zc_programme_version_immutable → ZCARE_PROGRAMME_VERSION_IMMUTABLE; ck_…_publication → ZCARE_CLINICAL_APPROVAL_REQUIRED. | E14: BE | F14: 04D §9.3; 04B §6 | G14: Not started
A15: M04-07 | B15: 2 Rules | C15: Programme and version lifecycles | D15: Programme draft → active → suspended → retired; version draft → pending_approval → published → retired. | E15: BE | F15: mig-05; DM | G15: Not started
A16: M04-08 | B16: 2 Rules | C16: Clinical approval gate | D16: Publish only after a clinician records approval; otherwise ZCARE_CLINICAL_APPROVAL_REQUIRED (HARD_STOP). | E16: BE | F16: ZCR-PRG-004; ADD Part E | G16: Not started
A17: M04-09 | B17: 2 Rules | C17: Published versions are frozen | D17: A material change creates a new version; the trigger rejects edits and the service refuses them first. | E17: BE | F17: ZCR-PRG-005/006; 04A INV-3 | G17: Not started
A18: M04-10 | B18: 2 Rules | C18: Freeze child configuration too | D18: Templates, gap rules, task/observation/goal types and outcome definitions of a published version are refused in code (DB does not protect them). | E18: BE | F18: 04D §2.3, §20 | G18: Not started
A19: M04-11 | B19: 2 Rules | C19: Suspend and retire safely | D19: Suspend new enrolments; retire with typed confirmation; never delete participation history. | E19: BE | F19: ZCR-PRG-007; 04C §8 | G19: Not started
A20: M04-12 | B20: 2 Rules | C20: Vocabulary as data | D20: Care models, codes and types seeded as rows, never as CHECK constraints; care_model free text until OD-15 closes. | E20: BE | F20: 04D §2.3 (P4); OD-15 | G20: Not started
... A38: M04-30 | B38: 8 Gate out | C38: Release v0.4.0 tagged | D38: Annotated tag v0.4.0 from a green pipeline; CHANGELOG section dated; next SNAPSHOT set. Dashboard now shows 100%. | E38: BE | F38: STD REL-01, REL-04, REL-07 | G38: Not started

Sheet M05 Reference
A1: M05 · External References | J1: ← Dashboard
A2: Goal | B2: Keep only the minimum details about members from outside systems, clearly marked as copies.
A3: Owns | B3: domains.reference: zc_member_reference, zc_external_reference (mig-04)
A4: Plan | B4: Depends on M04 · Sprints S11 · Screens Members list, member header · Release v0.5.0
A5: Done when | B5: Every copied detail shows its source and date, and if ZPS is down users see a clear message, never a silent gap.
A6: Progress | B6: =IF(D6=0,0,F6/D6) -> 0 | C6: Tasks | D6: =COUNTA(C9:C400) -> 26 | E6: Done or N/A | F6: =COUNTIF(G9:G400,"Done")+COUNTIF(G9:G400,"N/A") -> 0 | G6: Blocked | H6: =COUNTIF(G9:G400,"Blocked") -> 0 | I6: State | J6: =IF(B6=1,"Complete",IF(H6>0,"Blocked",IF(F6+COUNTIF(G9:G400,"In progress")=0,"Not started","In progress"))) -> Not started
A7: =IF('M04 Programme'!$B$6=1,"READY: M04 is complete. Work the steps in order, 0 Gate in to 8 Gate out.","LOCKED: finish M04 Programme first. Do not start work on this sheet.") -> LOCKED: finish M04 Programme first. Do not start work on this sheet.
A8: # | B8: Step | C8: Task | D8: Detail / done when | E8: Team | F8: Ref | G8: Status | H8: Owner | I8: Date done | J8: Notes / evidence
A9: M05-01 | B9: 0 Gate in | C9: Confirm M04 is signed off | D9: Dashboard shows M04 at 100% and its Gate out rows are Done. Do not start this sheet before that. | E9: PO | F9: RM §2.2 | G9: Not started
A10: M05-02 | B10: 0 Gate in | C10: Re-read this domain's specs | D10: PRD §12.1–12.6, §10.5; 04A §9, §13–14, §20; 04B §13; 04C §10.4; mig-04. | E10: BE, FE | F10: AGENTS "Source precedence" | G10: Not started
A11: M05-03 | B11: 0 Gate in | C11: Close the open decisions needed here | D11: Open Decisions sheet: OD-09 marked Decided, with the ADR or doc that records each. | E11: PO, BE | F11: OD sheet | G11: Not started
A12: M05-04 | B12: 1 Data | C12: Map owned tables to JPA entities | D12: zc_member_reference, zc_external_reference. Identity ids never supplied; @Version on row_version; tenant_id and created_* not updatable; entities stay inside the service layer. | E12: BE | F12: mig-04; 04D §11; ADR-0002 | G12: Not started
A13: M05-05 | B13: 1 Data | C13: Repositories and Specifications | D13: Spring Data repositories and <X>Specifications for search; every query runs inside the tenant context (RLS); lists are paged thin projections. | E13: BE | F13: 04F §8; STD JPA-11 | G13: Not started
A14: M05-06 | B14: 1 Data | C14: Translate constraint violations to exception codes | D14: Unique reference per (source_system, member number, individual) → duplicate absorbed; ck_…_non_auth → copies can never be authoritative. | E14: BE | F14: 04D §9.3; 04B §6 | G14: Not started
A15: M05-07 | B15: 2 Rules | C15: Minimum copy only | D15: Name, phone, payer number plus source_system and source_date; is_authoritative always false. | E15: BE | F15: PRD §12.6; 04A INV-9 | G15: Not started
A16: M05-08 | B16: 2 Rules | C16: Never store another system's record | D16: No member master, benefits, claims, pre-auth, prescriptions or dispensing data. | E16: BE | F16: 04D §2; PRD §12.5 | G16: Not started
A17: M05-09 | B17: 2 Rules | C17: PayerPort and ZPS/Eagle adapter | D17: Vendor-neutral port; adapter uses harness verbs identify_member and check_eligibility; no direct database access. | E17: BE | F17: 04B §13; ZCR-INT-003; STD INT-04 | G17: Not started
A18: M05-10 | B18: 2 Rules | C18: Resilience on the payer call | D18: Timeouts, circuit breaker, bounded retry on reads; failure returns ZCARE_EXTERNAL_DEPENDENCY_UNAVAILABLE (WARNING, retry), never a 500. | E18: BE | F18: ADD A10; STD RES-02..04 | G18: Not started
A19: M05-11 | B19: 2 Rules | C19: Reference snapshot with staleness | D19: Cache the reference snapshot; mark it stale after the agreed age. | E19: BE | F19: 04B §13; 04C §10.4 | G19: Not started
A20: M05-12 | B20: 3 API | C20: GET /members/{ref}/care-context (header part) | D20: Composes the reference with ZCare records; non-health header now, consent-gated body from M07. | E20: BE | F20: 04B §11 | G20: Not started
... A34: M05-26 | B34: 8 Gate out | C34: Release v0.5.0 tagged | D34: Annotated tag v0.5.0 from a green pipeline; CHANGELOG section dated; next SNAPSHOT set. Dashboard now shows 100%. | E34: BE | F34: STD REL-01, REL-04, REL-07 | G34: Not started

Sheet M06 Cohort
A1: M06 · Population & Cohort | J1: ← Dashboard
A2: Goal | B2: Receive eligible members from the payer and group them, reviewed, ready for invitation.
A3: Owns | B3: domains.cohort: zc_cohort, zc_cohort_run, zc_cohort_membership (mig-06)
A4: Plan | B4: Depends on M05 · Sprints S12–S13 · Screens S-08 · Release v0.6.0
A5: Done when | B5: A member sent by the payer appears as ready to invite, and a message without a valid signature is rejected, logged and changes nothing.
A6: Progress | B6: =IF(D6=0,0,F6/D6) -> 0 | C6: Tasks | D6: =COUNTA(C9:C400) -> 27 | E6: Done or N/A | F6: =COUNTIF(G9:G400,"Done")+COUNTIF(G9:G400,"N/A") -> 0 | G6: Blocked | H6: =COUNTIF(G9:G400,"Blocked") -> 0 | I6: State | J6: =IF(B6=1,"Complete",IF(H6>0,"Blocked",IF(F6+COUNTIF(G9:G400,"In progress")=0,"Not started","In progress"))) -> Not started
A7: =IF('M05 Reference'!$B$6=1,"READY: M05 is complete. Work the steps in order, 0 Gate in to 8 Gate out.","LOCKED: finish M05 Reference first. Do not start work on this sheet.") -> LOCKED: finish M05 Reference first. Do not start work on this sheet.
A8: # | B8: Step | C8: Task | D8: Detail / done when | E8: Team | F8: Ref | G8: Status | H8: Owner | I8: Date done | J8: Notes / evidence
A9: M06-01 | B9: 0 Gate in | C9: Confirm M05 is signed off | D9: Dashboard shows M05 at 100% and its Gate out rows are Done. Do not start this sheet before that. | E9: PO | F9: RM §2.2 | G9: Not started
A10: M06-02 | B10: 0 Gate in | C10: Re-read this domain's specs | D10: PRD §8.3; 04A §7.2 (DEC-003); 04B §10; 04C S-08; ADD A10–A11; mig-06. | E10: BE, FE | F10: AGENTS "Source precedence" | G10: Not started
A11: M06-03 | B11: 1 Data | C11: Map owned tables to JPA entities | D11: zc_cohort, zc_cohort_run, zc_cohort_membership. Identity ids never supplied; @Version on row_version; tenant_id and created_* not updatable; entities stay inside the service layer. | E11: BE | F11: mig-06; 04D §11; ADR-0002 | G11: Not started
A12: M06-04 | B12: 1 Data | C12: Repositories and Specifications | D12: Spring Data repositories and <X>Specifications for search; every query runs inside the tenant context (RLS); lists are paged thin projections. | E12: BE | F12: 04F §8; STD JPA-11 | G12: Not started
A13: M06-05 | B13: 1 Data | C13: Translate constraint violations to exception codes | D13: uq membership → repeat identification absorbed; pending_review run → ZCARE_COHORT_REVIEW_REQUIRED (ESCALATE). | E13: BE | F13: 04D §9.3; 04B §6 | G13: Not started
A14: M06-06 | B14: 2 Rules | C14: Cohort lifecycle | D14: Per programme version: draft → active → closed. | E14: BE | F14: mig-06 | G14: Not started
A15: M06-07 | B15: 2 Rules | C15: Condition-agnostic identification | D15: Core asks PayerPort for members flagged with the programme condition; Eagle adapter matches AilmentType Diabetes and Diabeties, never ICD codes. | E15: BE | F15: 04A §7.2, §20; 04B §21 | G15: Not started
A16: M06-08 | B16: 2 Rules | C16: Hold implausible volumes | D16: Run goes to pending_review with a hold reason; a person releases or rejects it. | E16: BE | F16: UC-ZC-011 E2; mig-06 | G16: Not started
A17: M06-09 | B17: 2 Rules | C17: Membership provenance | D17: Inclusion method, reason and source date on every member; removal needs a reason; history kept. | E17: BE | F17: ZCR-COH-003 | G17: Not started
A18: M06-10 | B18: 2 Rules | C18: Membership is not enrolment | D18: Admin review and release before any contact; auto-invite setting off by default. | E18: BE | F18: ZCR-COH-004; RM BE-M6 | G18: Not started
A19: M06-11 | B19: 2 Rules | C19: Signed payer webhooks | D19: /webhooks/payer/* (new members, leavers, reconciliations) verified with HMAC-SHA256; duplicates absorbed via the inbox. | E19: BE, SEC | F19: RM BE-M6; 04D §17 | G19: Not started
A20: M06-12 | B20: 3 API | C20: POST /cohorts, /cohorts/{id}/members, /cohorts/{id}:identify | D20: Programme admin; identify returns the run and its review state. | E20: BE | F20: 04B §10 | G20: Not started
... A35: M06-27 | B35: 8 Gate out | C35: Release v0.6.0 tagged | D35: Annotated tag v0.6.0 from a green pipeline; CHANGELOG section dated; next SNAPSHOT set. Dashboard now shows 100%. | E35: BE | F35: STD REL-01, REL-04, REL-07 | G35: Not started

Sheet M07 Enrolment
A1: M07 · Enrolment, Consent & Preferences | J1: ← Dashboard
A2: Goal | B2: Invite members, record their consent and start their care, never without consent.
A3: Owns | B3: domains.enrolment: zc_enrolment, zc_consent_record, zc_member_preference (mig-07)
A4: Plan | B4: Depends on M06 · Sprints S14–S16 · Screens S-02, S-06, S-15, S-16 · Release v0.7.0
A5: Done when | B5: No one can be activated without valid consent, and withdrawn consent blocks every action and cancels follow-on work.
A6: Progress | B6: =IF(D6=0,0,F6/D6) -> 0 | C6: Tasks | D6: =COUNTA(C9:C400) -> 38 | E6: Done or N/A | F6: =COUNTIF(G9:G400,"Done")+COUNTIF(G9:G400,"N/A") -> 0 | G6: Blocked | H6: =COUNTIF(G9:G400,"Blocked") -> 0 | I6: State | J6: =IF(B6=1,"Complete",IF(H6>0,"Blocked",IF(F6+COUNTIF(G9:G400,"In progress")=0,"Not started","In progress"))) -> Not started
A7: =IF('M06 Cohort'!$B$6=1,"READY: M06 is complete. Work the steps in order, 0 Gate in to 8 Gate out.","LOCKED: finish M06 Cohort first. Do not start work on this sheet.") -> LOCKED: finish M06 Cohort first. Do not start work on this sheet.
A8: # | B8: Step | C8: Task | D8: Detail / done when | E8: Team | F8: Ref | G8: Status | H8: Owner | I8: Date done | J8: Notes / evidence
A9: M07-01 | B9: 0 Gate in | C9: Confirm M06 is signed off | D9: Dashboard shows M06 at 100% and its Gate out rows are Done. Do not start this sheet before that. | E9: PO | F9: RM §2.2 | G9: Not started
A10: M07-02 | B10: 0 Gate in | C10: Re-read this domain's specs | D10: PRD §8.4; 04A §7.3, §16, §22.1; 04B §10 (enrolments), §6; 04C S-02, S-06, S-15, S-16, W-1; ADD A1–A5, D; mig-07. | E10: BE, FE | F10: AGENTS "Source precedence" | G10: Not started
A11: M07-03 | B11: 0 Gate in | C11: Close the open decisions needed here | D11: Open Decisions sheet: OD-16, OD-19, OD-30 marked Decided, with the ADR or doc that records each. | E11: PO, BE | F11: OD sheet | G11: Not started
A12: M07-04 | B12: 1 Data | C12: Map owned tables to JPA entities | D12: zc_enrolment, zc_consent_record, zc_member_preference. Identity ids never supplied; @Version on row_version; tenant_id and created_* not updatable; entities stay inside the service layer. | E12: BE | F12: mig-07; 04D §11; ADR-0002 | G12: Not started
A13: M07-05 | B13: 1 Data | C13: Repositories and Specifications | D13: Spring Data repositories and <X>Specifications for search; every query runs inside the tenant context (RLS); lists are paged thin projections. | E13: BE | F13: 04F §8; STD JPA-11 | G13: Not started
A14: M07-06 | B14: 1 Data | C14: Translate constraint violations to exception codes | D14: uq_zc_enrolment_one_active → ZCARE_ENROLMENT_DUPLICATE (WARNING); trg_zc_enrolment_pins → programme version fixed at invitation. | E14: BE | F14: 04D §9.3; 04B §6 | G14: Not started
A15: M07-07 | B15: 2 Rules | C15: Invite | D15: Eligibility check via PayerPort; enrolment created as invited with the programme version pinned; eligibility snapshot kept non-authoritative. | E15: BE | F15: ZCR-ENR-001, ENR-004; 04A §22.1 | G15: Not started
A16: M07-08 | B16: 2 Rules | C16: Enrolment lifecycle | D16: invited → active → suspended → completed → withdrawn; one active enrolment per member and programme; exit needs reason and date; history never deleted. | E16: BE | F16: ZCR-ENR-005..007; 04A INV-1 | G16: Not started
A17: M07-09 | B17: 2 Rules | C17: Consent record | D17: captured → validated → revoked / scope_reduced / superseded; one in force; wording version and channel; revocation keeps the verbatim text. | E17: BE | F17: mig-07; DEC-021 | G17: Not started
A18: M07-10 | B18: 2 Rules | C18: ConsentGateService (one for everything) | D18: Checked when acting, sending and viewing; missing → ZCARE_CONSENT_REQUIRED (ESCALATE, request_consent); revoked → ZCARE_CONSENT_REVOKED (HARD_STOP); never a 409. | E18: BE | F18: RM BE-M7; 04B §2, §6; 04D §9.4 | G18: Not started
A19: M07-11 | B19: 2 Rules | C19: Activation by the care manager | D19: Never automatic on consent; needs validated consent and a responsible care manager; nextActions create_care_plan, assign_task; audit ACTIVATE_ENROLMENT. | E19: BE | F19: 04B §20; 04C J3 | G19: Not started
A20: M07-12 | B20: 2 Rules | C20: Suspend and withdraw | D20: Mandatory reason; exit cancels open work and refills with a truthful label (consent_revoked or enrolment_ended), via events consumed in M10/M12. | E20: BE | F20: ADD A1, A2 | G20: Not started
... A46: M07-38 | B46: 8 Gate out | C46: Release v0.7.0 tagged | D46: Annotated tag v0.7.0 from a green pipeline; CHANGELOG section dated; next SNAPSHOT set. Dashboard now shows 100%. | E46: BE | F46: STD REL-01, REL-04, REL-07 | G46: Not started

Sheet M08 Assessment
A1: M08 · Assessment & Risk | J1: ← Dashboard
A2: Goal | B2: Run health questionnaires and set a priority level for each member.
A3: Owns | B3: domains.assessment: zc_assessment, zc_assessment_response, zc_risk_classification (mig-08)
A4: Plan | B4: Depends on M07 · Sprints S17–S18 · Screens S-09 · Release v0.8.0
A5: Done when | B5: The same answers always give the same score, and every override has a reason.
A6: Progress | B6: =IF(D6=0,0,F6/D6) -> 0 | C6: Tasks | D6: =COUNTA(C9:C400) -> 29 | E6: Done or N/A | F6: =COUNTIF(G9:G400,"Done")+COUNTIF(G9:G400,"N/A") -> 0 | G6: Blocked | H6: =COUNTIF(G9:G400,"Blocked") -> 0 | I6: State | J6: =IF(B6=1,"Complete",IF(H6>0,"Blocked",IF(F6+COUNTIF(G9:G400,"In progress")=0,"Not started","In progress"))) -> Not started
A7: =IF('M07 Enrolment'!$B$6=1,"READY: M07 is complete. Work the steps in order, 0 Gate in to 8 Gate out.","LOCKED: finish M07 Enrolment first. Do not start work on this sheet.") -> LOCKED: finish M07 Enrolment first. Do not start work on this sheet.
A8: # | B8: Step | C8: Task | D8: Detail / done when | E8: Team | F8: Ref | G8: Status | H8: Owner | I8: Date done | J8: Notes / evidence
A9: M08-01 | B9: 0 Gate in | C9: Confirm M07 is signed off | D9: Dashboard shows M07 at 100% and its Gate out rows are Done. Do not start this sheet before that. | E9: PO | F9: RM §2.2 | G9: Not started
A10: M08-02 | B10: 0 Gate in | C10: Re-read this domain's specs | D10: PRD §8.5; 04A §7.4; 04B §10; 04C S-09, W-3; 04E §1; mig-08. | E10: BE, FE | F10: AGENTS "Source precedence" | G10: Not started
A11: M08-03 | B11: 0 Gate in | C11: Close the open decisions needed here | D11: Open Decisions sheet: OD-15, OD-16 marked Decided, with the ADR or doc that records each. | E11: PO, BE | F11: OD sheet | G11: Not started
A12: M08-04 | B12: 1 Data | C12: Map owned tables to JPA entities | D12: zc_assessment, zc_assessment_response, zc_risk_classification. Identity ids never supplied; @Version on row_version; tenant_id and created_* not updatable; entities stay inside the service layer. | E12: BE | F12: mig-08; 04D §11; ADR-0002 | G12: Not started
A13: M08-05 | B13: 1 Data | C13: Map append-only tables as insert-only | D13: zc_assessment_response, zc_risk_classification: INSERT and SELECT only; a change is a new row (trigger and privilege already enforce it). | E13: BE | F13: 04D §11; mig-20 | G13: Not started
A14: M08-06 | B14: 1 Data | C14: Repositories and Specifications | D14: Spring Data repositories and <X>Specifications for search; every query runs inside the tenant context (RLS); lists are paged thin projections. | E14: BE | F14: 04F §8; STD JPA-11 | G14: Not started
A15: M08-07 | B15: 1 Data | C15: Translate constraint violations to exception codes | D15: trg_zc_assessment_pins → template version fixed at assignment; ck_…_override → override needs a reason. | E15: BE | F15: 04D §9.3; 04B §6 | G15: Not started
A16: M08-08 | B16: 2 Rules | C16: Assessment lifecycle | D16: assigned → in_progress → completed / cancelled / expired, pinned to the template version. | E16: BE | F16: mig-08 | G16: Not started
A17: M08-09 | B17: 2 Rules | C17: Append-only answers | D17: A changed answer is a new row; the latest answer wins. | E17: BE | F17: ZCR-ASM-002; 04D | G17: Not started
A18: M08-10 | B18: 2 Rules | C18: Deterministic scoring | D18: Scores from the pinned version's scoring rules only; score_detail explains the result; never scored complete when incomplete. | E18: BE | F18: ZCR-ASM-003; 04E §1 | G18: Not started
A19: M08-11 | B19: 2 Rules | C19: Priority, never diagnosis | D19: Risk classification is append-only programme priority; tier names free text until OD-15 closes. | E19: BE | F19: ZCR-ASM-004; ADD D | G19: Not started
A20: M08-12 | B20: 2 Rules | C20: Clinician confirm or override | D20: Override creates a new row linked to the one it overrides, with a reason. | E20: BE | F20: ZCR-ASM-005 | G20: Not started
... A37: M08-29 | B37: 8 Gate out | C37: Release v0.8.0 tagged | D37: Annotated tag v0.8.0 from a green pipeline; CHANGELOG section dated; next SNAPSHOT set. Dashboard now shows 100%. | E37: BE | F37: STD REL-01, REL-04, REL-07 | G37: Not started

Sheet M09 Care Plan
A1: M09 · Care Planning | J1: ← Dashboard
A2: Goal | B2: Create care plans with measurable goals that a clinician approves, never the person who wrote them.
A3: Owns | B3: domains.careplan: zc_care_plan, zc_goal, zc_intervention, zc_care_plan_link, zc_plan_review (mig-09)
A4: Plan | B4: Depends on M08 · Sprints S19–S21 · Screens S-03, S-13 · Release v0.9.0
A5: Done when | B5: Only a clinician activates a plan, authors cannot approve their own plans, and each member has one active plan.
A6: Progress | B6: =IF(D6=0,0,F6/D6) -> 0 | C6: Tasks | D6: =COUNTA(C9:C400) -> 32 | E6: Done or N/A | F6: =COUNTIF(G9:G400,"Done")+COUNTIF(G9:G400,"N/A") -> 0 | G6: Blocked | H6: =COUNTIF(G9:G400,"Blocked") -> 0 | I6: State | J6: =IF(B6=1,"Complete",IF(H6>0,"Blocked",IF(F6+COUNTIF(G9:G400,"In progress")=0,"Not started","In progress"))) -> Not started
A7: =IF('M08 Assessment'!$B$6=1,"READY: M08 is complete. Work the steps in order, 0 Gate in to 8 Gate out.","LOCKED: finish M08 Assessment first. Do not start work on this sheet.") -> LOCKED: finish M08 Assessment first. Do not start work on this sheet.
A8: # | B8: Step | C8: Task | D8: Detail / done when | E8: Team | F8: Ref | G8: Status | H8: Owner | I8: Date done | J8: Notes / evidence
A9: M09-01 | B9: 0 Gate in | C9: Confirm M08 is signed off | D9: Dashboard shows M08 at 100% and its Gate out rows are Done. Do not start this sheet before that. | E9: PO | F9: RM §2.2 | G9: Not started
A10: M09-02 | B10: 0 Gate in | C10: Re-read this domain's specs | D10: PRD §8.6; 04A §7.5, §22.2; 04B §10; 04C S-03, S-13; ADD A6, Part E, D; mig-09. | E10: BE, FE | F10: AGENTS "Source precedence" | G10: Not started
A11: M09-03 | B11: 0 Gate in | C11: Close the open decisions needed here | D11: Open Decisions sheet: OD-16, OD-17, OD-20 marked Decided, with the ADR or doc that records each. | E11: PO, BE | F11: OD sheet | G11: Not started
A12: M09-04 | B12: 1 Data | C12: Map owned tables to JPA entities | D12: zc_care_plan, zc_goal, zc_intervention, zc_care_plan_link, zc_plan_review. Identity ids never supplied; @Version on row_version; tenant_id and created_* not updatable; entities stay inside the service layer. | E12: BE | F12: mig-09; 04D §11; ADR-0002 | G12: Not started
A13: M09-05 | B13: 1 Data | C13: Map append-only tables as insert-only | D13: zc_plan_review: INSERT and SELECT only; a change is a new row (trigger and privilege already enforce it). | E13: BE | F13: 04D §11; mig-20 | G13: Not started
A14: M09-06 | B14: 1 Data | C14: Repositories and Specifications | D14: Spring Data repositories and <X>Specifications for search; every query runs inside the tenant context (RLS); lists are paged thin projections. | E14: BE | F14: 04F §8; STD JPA-11 | G14: Not started
A15: M09-07 | B15: 1 Data | C15: Translate constraint violations to exception codes | D15: trg_zc_care_plan_approval_immutable → ZCARE_PLAN_VERSION_IMMUTABLE; uq_zc_care_plan_one_active → one active plan; ck_zc_goal_measurable → field error naming the goal. | E15: BE | F15: 04D §9.3; 04B §6 | G15: Not started
A16: M09-08 | B16: 2 Rules | C16: Plan lifecycle | D16: draft → pending_approval → active; request changes → draft; reject → rejected; then revised, suspended, completed, closed. | E16: BE | F16: 04A §22.2; mig-09 | G16: Not started
A17: M09-09 | B17: 2 Rules | C17: Clinician-only approval, author excluded | D17: Approver must be a clinician and not the author (code; DB does not check); others get 403 from the filter layer. | E17: BE, SEC | F17: RM §1.2, BE-M9; ADD Part E | G17: Not started
A18: M09-10 | B18: 2 Rules | C18: Approval is final | D18: Approver and time write-once; never approved by timeout; no bulk approve. | E18: BE | F18: mig-09; ADD D | G18: Not started
A19: M09-11 | B19: 2 Rules | C19: Measurable goals | D19: Every goal has a target value and unit or criteria; a plan with zero goals cannot be submitted. | E19: BE | F19: ck_zc_goal_measurable; ADD A6 | G19: Not started
A20: M09-12 | B20: 2 Rules | C20: Revisions keep history | D20: A revision copies goals and open interventions; the previous version keeps its approver. | E20: BE | F20: ZCR-CRP-004; ADD A6 | G20: Not started
... A40: M09-32 | B40: 8 Gate out | C40: Release v0.9.0 tagged | D40: Annotated tag v0.9.0 from a green pipeline; CHANGELOG section dated; next SNAPSHOT set. Dashboard now shows 100%. | E40: BE | F40: STD REL-01, REL-04, REL-07 | G40: Not started

Sheet M10 Care Work
A1: M10 · Care Work | J1: ← Dashboard
A2: Goal | B2: Turn plans and alerts into clear, prioritised to-do lists for the care team.
A3: Owns | B3: domains.carework: zc_task, zc_task_dependency, zc_task_assignment_history, zc_work_queue_definition (mig-10)
A4: Plan | B4: Depends on M09 · Sprints S22–S23 · Screens S-01 · Release v0.10.0
A5: Done when | B5: Each care manager has a prioritised queue that loads in under half a second at pilot scale, and overdue work is flagged.
A6: Progress | B6: =IF(D6=0,0,F6/D6) -> 0 | C6: Tasks | D6: =COUNTA(C9:C400) -> 32 | E6: Done or N/A | F6: =COUNTIF(G9:G400,"Done")+COUNTIF(G9:G400,"N/A") -> 0 | G6: Blocked | H6: =COUNTIF(G9:G400,"Blocked") -> 0 | I6: State | J6: =IF(B6=1,"Complete",IF(H6>0,"Blocked",IF(F6+COUNTIF(G9:G400,"In progress")=0,"Not started","In progress"))) -> Not started
A7: =IF('M09 Care Plan'!$B$6=1,"READY: M09 is complete. Work the steps in order, 0 Gate in to 8 Gate out.","LOCKED: finish M09 Care Plan first. Do not start work on this sheet.") -> LOCKED: finish M09 Care Plan first. Do not start work on this sheet.
A8: # | B8: Step | C8: Task | D8: Detail / done when | E8: Team | F8: Ref | G8: Status | H8: Owner | I8: Date done | J8: Notes / evidence
A9: M10-01 | B9: 0 Gate in | C9: Confirm M09 is signed off | D9: Dashboard shows M09 at 100% and its Gate out rows are Done. Do not start this sheet before that. | E9: PO | F9: RM §2.2 | G9: Not started
A10: M10-02 | B10: 0 Gate in | C10: Re-read this domain's specs | D10: PRD §8.7; 04A §7.6; 04B §10–11; 04C S-01; ADD A1, B, E; mig-10. | E10: BE, FE | F10: AGENTS "Source precedence" | G10: Not started
A11: M10-03 | B11: 0 Gate in | C11: Close the open decisions needed here | D11: Open Decisions sheet: OD-16, OD-29 marked Decided, with the ADR or doc that records each. | E11: PO, BE | F11: OD sheet | G11: Not started
A12: M10-04 | B12: 1 Data | C12: Map owned tables to JPA entities | D12: zc_task, zc_task_dependency, zc_task_assignment_history, zc_work_queue_definition. Identity ids never supplied; @Version on row_version; tenant_id and created_* not updatable; entities stay inside the service layer. | E12: BE | F12: mig-10; 04D §11; ADR-0002 | G12: Not started
A13: M10-05 | B13: 1 Data | C13: Map append-only tables as insert-only | D13: zc_task_assignment_history: INSERT and SELECT only; a change is a new row (trigger and privilege already enforce it). | E13: BE | F13: 04D §11; mig-20 | G13: Not started
A14: M10-06 | B14: 1 Data | C14: Repositories and Specifications | D14: Spring Data repositories and <X>Specifications for search; every query runs inside the tenant context (RLS); lists are paged thin projections. | E14: BE | F14: 04F §8; STD JPA-11 | G14: Not started
A15: M10-07 | B15: 1 Data | C15: Translate constraint violations to exception codes | D15: trg_zc_task_dependency_gate → task blocked by an open prerequisite; restricted completion → ZCARE_TASK_RESTRICTED (ESCALATE, in the envelope, not 403). | E15: BE | F15: 04D §9.3; 04B §6 | G15: Not started
A16: M10-08 | B16: 2 Rules | C16: Task lifecycle | D16: assigned → accepted → in_progress → blocked → completed / cancelled; priority 1–5; assignee is a person or a role. | E16: BE | F16: mig-10 | G16: Not started
A17: M10-09 | B17: 2 Rules | C17: Tasks from earlier domains | D17: Consume events: PLAN_APPROVAL on plan submit, intervention tasks on plan activation, expired assessments, cancellations on enrolment exit with the right label. | E17: BE | F17: ADD A1, Part E | G17: Not started
A18: M10-10 | B18: 2 Rules | C18: Dependencies | D18: A task cannot complete while a prerequisite is open; removing a dependency needs a reason. | E18: BE | F18: mig-10 | G18: Not started
A19: M10-11 | B19: 2 Rules | C19: Reassignment history | D19: Every reassignment appends a row; cancel needs a reason. | E19: BE | F19: ZCR-WRK-004 | G19: Not started
A20: M10-12 | B20: 2 Rules | C20: Restricted task types | D20: PLAN_APPROVAL, THRESHOLD_REVIEW and similar completable only by their role owner. | E20: BE | F20: UC-ZC-003 E1; ADD B | G20: Not started
... A40: M10-32 | B40: 8 Gate out | C40: Release v0.10.0 tagged | D40: Annotated tag v0.10.0 from a green pipeline; CHANGELOG section dated; next SNAPSHOT set. Dashboard now shows 100%. | E40: BE | F40: STD REL-01, REL-04, REL-07 | G40: Not started

Sheet M11 Referral
